Workbook

Sheet 監廚__(10)
A1: 中央警察大學 92期1隊 114學年度第2學期監廚勤務表 (第 週)
A2: 日期 | B2: 9月22日 | D2: 9月23日 | F2: 9月24日 | H2: 9月25日 | J2: 9月26日
A3: 星期 | B3: 一 | D3: 二 | F3: 三 | H3: 四 | J3: 五
A4: 0900-1000
A6: 1000-1100
A8: 1500-1600
A10: 1600-1700
A12: 備註： 1、輪值勤務，請同學務必提早5-10分鐘到勤。 2、請同學互相提醒值勤時間。 3、如有疑問(如衝堂、因故無法值班等)，請向勤務排表員921127江睿承(B218)、921165謝頡譯(B218)反應。 4、本表公布後，請同學於自己名字下方簽名(押時間)確認，如需更改，請報由區隊長核章修正，若逾時未簽名者，將依規定記點處分。

Sheet 114-1_W13_總隊值星_
A1: 中央警察大學 92期1隊 114學年度第2學期 總隊值星週隊部值班表 (第 週)
A2: 日期 | B2: 11月23日 | D2: 11月24日 | F2: 11月25日 | H2: 11月26日 | J2: 11月27日 | L2: 11月28日
A3: 星期 | B3: 日 | D3: 一 | F3: 二 | H3: 三 | J3: 四 | L3: 五
A4: 0000-0200
A6: 0200-0400
A8: 0400-0600
A10: 0600-0800
A12: 0800-1000
A14: 1000-1200
A16: 1200-1350
A18: 1350-1550
A20: 1550-1800
A22: 1800-2000
A24: 2000-2200
A26: 2200-0000
A28: 備註： 1、輪值勤務，請同學務必提早5-10分鐘到勤。 2、請同學互相提醒值勤時間，特別是夜間值班同學。 3、如有疑問(如衝堂、因故無法值班等)，請向勤務排表員921127江睿承(B218)、921165謝頡譯(B218)反應。 4、本表公布後，請同學於自己名字下方簽名(押時間)確認，如需更改，請報由區隊長核章修正，收假前未簽名確認者，將依規定記點處分。

Sheet 114-1_W13警技館
A1: 中央警察大學 92期1隊 114學年度第2學期 警技館值班勤務表 (第 週)
A2: 日期 | B2: 11月21日 | D2: 11月24日 | F2: 11月25日 | H2: 11月26日 | J2: 11月27日
A3: 星期 | B3: 五 | D3: ㄧ | F3: 二 | H3: 三 | J3: 四
A4: 17：00- 18：00
A6: 18：00- 20：00
A8: 20：00- 22：00
A10: 備註： 1、值班同學於警技館三樓重訓室旁之裁判休息室擔服值班勤務(著期服或黑運)，值班時需注意並留心學生、場館及器材的安全狀況。 2、擔任服最後一班勤務(2000-2200)的同學，須於2150開始進行警技館出入管制 (只出不進)，並於2200進行清場，在確認警技館內(3樓-B1)已無人員逗留後，方能將燈火全數關閉並退勤 3、警技館值班同學先至隊部簽到，再前往警技館簽到服勤，到勤後撥打電話向隊部值班同學回報。 4、如有疑問(如衝堂、因故無法值班等)，請向勤務排表員921127江睿承(B218)、921165謝頡譯(B218)反應。 5、本表公布後，請同學於名字下方簽名(押時間)確認，如需更改，請報由區隊長核章修正，若逾時未簽名者，將依規定記點處分。

Sheet 校巡_(7)
A1: 中央警察大學92期1隊114學年度第2學期 總隊值星假日校園巡邏勤務表 (第 週)
A2: 日期 | B2: 12月19日 | F2: 12月20日 | J2: 12月21日
A3: 星期 | B3: 五 | F3: 六 | J3: 日
A4: 0600-0800
A6: 0800-1000
A8: 1000-1200
A10: 1200-1400
A12: 1400-1600
A14: 1600-1800
A16: 1800-2000
A18: 2000-2200
A20: 2200-2400
A22: 備註： 1、擔服巡邏勤務，請著整齊服裝(勤務帽、制服、勤務鞋)，提前5-10分鐘至隊部簽到，並領取無線電、巡邏表及相關配件。 2、請同學互相提醒值勤時間，切勿脫勤。 3、如有疑問(如衝堂、因故無法值班等)，請向勤務排表員921127江睿承(B218)、921165謝頡譯(B218)反應。 4、本表公布後，請同學於自己名字下方簽名(押時間)確認，如需更改，請報由區隊長核章修正。

Sheet 114-2_W0始業週_(2)
A1: 中央警察大學 92期1隊 114學年度第2學期隊部值班表 (始業週)
A2: 日期 | B2: 2月22日 | D2: 2月23日 | F2: 2月24日 | H2: 2月25日 | J2: 2月26日 | L2: 2月27日
A3: 星期 | B3: 日 | D3: 一 | F3: 二 | H3: 三 | J3: 四 | L3: 五
A4: 0600-0800 | B4: 寒假 | D4: 78 | E4: =VLOOKUP(D4,[1]花名冊!$A$1:$C$290,2,FALSE) -> 溫俊宇 | F4: 217 | G4: =VLOOKUP(F4,[1]花名冊!$A$1:$C$290,2,FALSE) -> 蘇子瑋 | H4: 28 | I4: =VLOOKUP(H4,[1]花名冊!$A$1:$C$290,2,FALSE) -> 李昱穎 | J4: 150 | K4: =VLOOKUP(J4,[1]花名冊!$A$1:$C$290,2,FALSE) -> 黃博均 | L4: 和平紀念日放假
A6: 0800-1000 | D6: 190 | E6: =VLOOKUP(D6,[1]花名冊!$A$1:$C$290,2,FALSE) -> 邱御 | F6: 4 | G6: =VLOOKUP(F6,[1]花名冊!$A$1:$C$290,2,FALSE) -> 王湘霖 | H6: 208 | I6: =VLOOKUP(H6,[1]花名冊!$A$1:$C$290,2,FALSE) -> 林佐庚 | J6: 245 | K6: =VLOOKUP(J6,[1]花名冊!$A$1:$C$290,2,FALSE) -> 江昱廷
A8: 1000-1200 | D8: 102 | E8: =VLOOKUP(D8,[1]花名冊!$A$1:$C$290,2,FALSE) -> 涂詠超 | F8: 50 | G8: =VLOOKUP(F8,[1]花名冊!$A$1:$C$290,2,FALSE) -> 龔昱睿 | H8: 14 | I8: =VLOOKUP(H8,[1]花名冊!$A$1:$C$290,2,FALSE) -> 陳泊諺 | J8: 114 | K8: =VLOOKUP(J8,[1]花名冊!$A$1:$C$290,2,FALSE) -> 彭楷峰
A10: 1200-1350 | D10: 168 | E10: =VLOOKUP(D10,[1]花名冊!$A$1:$C$290,2,FALSE) -> 丁友竣 | F10: 18 | G10: =VLOOKUP(F10,[1]花名冊!$A$1:$C$290,2,FALSE) -> 張崇達 | H10: 127 | I10: =VLOOKUP(H10,[1]花名冊!$A$1:$C$290,2,FALSE) -> 江睿承 | J10: 66 | K10: =VLOOKUP(J10,[1]花名冊!$A$1:$C$290,2,FALSE) -> 郭亮廷
A12: 1350-1600 | D12: 138 | E12: =VLOOKUP(D12,[1]花名冊!$A$1:$C$290,2,FALSE) -> 陳昱丞 | F12: 19 | G12: =VLOOKUP(F12,[1]花名冊!$A$1:$C$290,2,FALSE) -> 黄丞昊 | H12: 213 | I12: =VLOOKUP(H12,[1]花名冊!$A$1:$C$290,2,FALSE) -> 沈宸右 | J12: 142 | K12: =VLOOKUP(J12,[1]花名冊!$A$1:$C$290,2,FALSE) -> 袁翊城
A14: 1600-1800 | D14: 197 | E14: =VLOOKUP(D14,[1]花名冊!$A$1:$C$290,2,FALSE) -> 黃鼎心 | F14: 165 | G14: =VLOOKUP(F14,[1]花名冊!$A$1:$C$290,2,FALSE) -> 謝頡譯 | H14: 94 | I14: =VLOOKUP(H14,[1]花名冊!$A$1:$C$290,2,FALSE) -> 李定宇 | J14: 36 | K14: =VLOOKUP(J14,[1]花名冊!$A$1:$C$290,2,FALSE) -> 黃逸宸
A16: 1800-2000 | D16: 160 | E16: =VLOOKUP(D16,[1]花名冊!$A$1:$C$290,2,FALSE) -> 賴仲倫 | F16: 129 | G16: =VLOOKUP(F16,[1]花名冊!$A$1:$C$290,2,FALSE) -> 陳頤紘 | H16: 2 | I16: =VLOOKUP(H16,[1]花名冊!$A$1:$C$290,2,FALSE) -> 方聖文 | J16: 放假
A18: 2000-2200 | B18: 29 | C18: =VLOOKUP(B18,[1]花名冊!$A$1:$C$290,2,FALSE) -> 陳維昇 | D18: 15 | E18: =VLOOKUP(D18,[1]花名冊!$A$1:$C$290,2,FALSE) -> 鄭弘侖 | F18: 140 | G18: =VLOOKUP(F18,[1]花名冊!$A$1:$C$290,2,FALSE) -> 吳承翰 | H18: 261 | I18: =VLOOKUP(H18,[1]花名冊!$A$1:$C$290,2,FALSE) -> 江育丞
B19: 2100-2200
A20: 2200-2300 | B20: 39 | C20: =VLOOKUP(B20,[1]花名冊!$A$1:$C$290,2,FALSE) -> 林智心 | D20: 236 | E20: =VLOOKUP(D20,[1]花名冊!$A$1:$C$290,2,FALSE) -> 陳韓英聖 | F20: 141 | G20: =VLOOKUP(F20,[1]花名冊!$A$1:$C$290,2,FALSE) -> 陳冠璋 | H20: 152 | I20: =VLOOKUP(H20,[1]花名冊!$A$1:$C$290,2,FALSE) -> 陳兆坤
A22: 備註： 1、輪值勤務，請同學務必提早5-10分鐘到勤。 2、請同學互相提醒值勤時間，特別是夜間值班同學。 3、如有疑問(如衝堂、因故無法值班等)，請向勤務排表員921171賴紹瑜(B412)、921107高振碩(B302)反應。 4、本表公布後，請同學於自己名字下方簽名(押時間)確認，如需更改，請報由區隊長核章修正，收假前未簽名確認者，將依規定記點處分。

Sheet 114-2_W0夜巡
A1: 中央警察大學 92期1隊 114學年度第2學期友誼、警英夜巡勤務表 (始業週)
A2: 日期 | B2: 2月22日 | D2: 2月23日 | F2: 2月24日 | H2: 2月25日 | J2: 2月26日 | L2: 2月27日
A3: 星期 | B3: 日 | D3: 一 | F3: 二 | H3: 三 | J3: 四 | L3: 五
A4: 01：00- 03：00 | B4: 放假 | D4: 223 | E4: =VLOOKUP(D4,[1]花名冊!$A$1:$C$290,2,FALSE) -> 王霖堯 | F4: 243 | G4: =VLOOKUP(F4,[1]花名冊!$A$1:$C$290,2,FALSE) -> 簡揆峰 | H4: 242 | I4: =VLOOKUP(H4,[1]花名冊!$A$1:$C$290,2,FALSE) -> 黃詡幃 | J4: 207 | K4: =VLOOKUP(J4,[1]花名冊!$A$1:$C$290,2,FALSE) -> 許家豪 | L4: 和平紀念日放假
D6: 257 | E6: =VLOOKUP(D6,[1]花名冊!$A$1:$C$290,2,FALSE) -> 林文斌 | F6: 55 | G6: =VLOOKUP(F6,[1]花名冊!$A$1:$C$290,2,FALSE) -> 陳厚成 | H6: 260 | I6: =VLOOKUP(H6,[1]花名冊!$A$1:$C$290,2,FALSE) -> 施松佑 | J6: 27 | K6: =VLOOKUP(J6,[1]花名冊!$A$1:$C$290,2,FALSE) -> 陳冠霖
A8: 03：00- 05：00 | D8: 11 | E8: =VLOOKUP(D8,[1]花名冊!$A$1:$C$290,2,FALSE) -> 吳兆陽 | F8: 63 | G8: =VLOOKUP(F8,[1]花名冊!$A$1:$C$290,2,FALSE) -> 潘家立 | H8: 273 | I8: =VLOOKUP(H8,[1]花名冊!$A$1:$C$290,2,FALSE) -> 江翊嘉 | J8: 169 | K8: =VLOOKUP(J8,[1]花名冊!$A$1:$C$290,2,FALSE) -> 林于泓
D10: 93 | E10: =VLOOKUP(D10,[1]花名冊!$A$1:$C$290,2,FALSE) -> 黃俊凱 | F10: 122 | G10: =VLOOKUP(F10,[1]花名冊!$A$1:$C$290,2,FALSE) -> 黃翊愷 | H10: 40 | I10: =VLOOKUP(H10,[1]花名冊!$A$1:$C$290,2,FALSE) -> 黃梓銘 | J10: 151 | K10: =VLOOKUP(J10,[1]花名冊!$A$1:$C$290,2,FALSE) -> 劉垣岑
A12: 23：00- 01：00 | B12: 75 | C12: =VLOOKUP(B12,[1]花名冊!$A$1:$C$290,2,FALSE) -> 張家瑞 | D12: 41 | E12: =VLOOKUP(D12,[1]花名冊!$A$1:$C$290,2,FALSE) -> 陳逸安 | F12: 26 | G12: =VLOOKUP(F12,[1]花名冊!$A$1:$C$290,2,FALSE) -> 蘇少芃 | H12: 172 | I12: =VLOOKUP(H12,[1]花名冊!$A$1:$C$290,2,FALSE) -> 陳緯澄 | J12: 放假
B14: 167 | C14: =VLOOKUP(B14,[1]花名冊!$A$1:$C$290,2,FALSE) -> 黃仁謙 | D14: 235 | E14: =VLOOKUP(D14,[1]花名冊!$A$1:$C$290,2,FALSE) -> 楊峻宇 | F14: 43 | G14: =VLOOKUP(F14,[1]花名冊!$A$1:$C$290,2,FALSE) -> 許家寶 | H14: 170 | I14: =VLOOKUP(H14,[1]花名冊!$A$1:$C$290,2,FALSE) -> 趙仁毅
A16: 備註： 1、擔服週間巡邏勤務，請著整齊服裝(勤務帽、制服、勤務鞋)，提前5-10分鐘至總隊值星隊簽到，並領取無線電、巡邏表及相關配件。 2、請同學互相提醒值勤時間，切勿脫勤。 3、如有疑問(如衝堂、因故無法值班等)，請向勤務排表員921107高振碩(B302)、921171賴紹瑜(B412)反應。 4、本表公布後，請同學於自己名字下方簽名(押時間)確認，如需更改，請報由區隊長核章修正，若收假前未簽名確認者，將依規定記點處分。

Sheet 114-2_W1_值班
A1: 中央警察大學 92期1隊 114學年度第2學期隊部值班表 (第1週)
A2: 日期 | B2: 3月2日 | D2: 3月3日 | F2: 3月4日 | H2: 3月5日 | J2: 3月6日
A3: 星期 | B3: 一 | D3: 二 | F3: 三 | H3: 四 | J3: 五
A4: 0600-0800 | B4: 40 | C4: 黃梓銘 | D4: 258 | E4: 林育新 | F4: 261 | G4: 江育丞 | H4: 240 | I4: 陳柏安 | J4: 206 | K4: 陳立峰
A6: 0800-1000 | B6: 137 | C6: 石宸華 | D6: 77 | E6: 劉俊亨 | F6: 82 | G6: 謝嘉文 | H6: 135 | I6: 黃浩昕 | J6: 114 | K6: 彭楷峰
A8: 1000-1200 | B8: 52 | C8: 蕭銘毅 | D8: 76 | E8: 徐晨恩 | F8: 207 | G8: 許家豪 | H8: 49 | I8: 黃振誠 | J8: 161 | K8: 姚以諾
A10: 1200-1350 | B10: 29 | C10: 陳維昇 | D10: 195 | E10: 王奕凱 | F10: 10 | G10: 林心鈺 | H10: 235 | I10: 楊峻宇 | J10: 148 | K10: 吳尚恩
A12: 1350-1600 | B12: 242 | C12: 黃詡幃 | D12: 100 | E12: 顏岑錡 | F12: 154 | G12: 陳伯軒 | H12: 102 | I12: 涂詠超 | J12: 124 | K12: 許燿安
A14: 1600-1800 | B14: 166 | C14: 陳俊富 | D14: 15 | E14: 鄭弘侖 | F14: 17 | G14: 粘宸愷 | H14: 70 | I14: 吳建霆 | J14: 237 | K14: 林揚傑
A16: 1800-2000 | B16: 80 | C16: 林昱凱 | D16: 101 | E16: 黃振瑋 | F16: 140 | G16: 吳承翰 | H16: 224 | I16: 陳奕廷 | J16: 放假
A18: 2000-2200 | B18: 130 | C18: 王紀雲 | D18: 278 | E18: 楊士霆 | F18: 263 | G18: 朱胤辰 | H18: 50 | I18: 龔昱睿
A20: 2200-2300 | B20: 170 | C20: 趙仁毅 | D20: 176 | E20: 林俞佑 | F20: 138 | G20: 陳昱丞 | H20: 123 | I20: 施瑀修
A22: 備註： 1、輪值勤務，請同學務必提早5-10分鐘到勤。 2、請同學互相提醒值勤時間，特別是夜間值班同學。 3、如有疑問(如衝堂、因故無法值班等)，請向勤務排表員921127江睿承(B218)、921165謝頡譯(B218)反應。 4、本表公布後，請同學於自己名字下方簽名(押時間)確認，如需更改，請報由區隊長核章修正，收假前未簽名確認者，將依規定記點處分。

Sheet 114-2_W1週間
A1: 中央警察大學 92期1隊 114學年度第2學期週間校巡勤務表 (第1週)
A2: 日期 | B2: 3月2日 | D2: 3月3日 | F2: 3月4日 | H2: 3月5日
A3: 星期 | B3: 一 | D3: 二 | F3: 三 | H3: 四
A4: 20：00- 22：00 | H4: 57 | I4: 陳冠佑
H6: 219 | I6: 徐子梁
A8: 22：00- 24：00 | H8: 122 | I8: 黃翊愷
H10: 172 | I10: 陳緯澄
A12: 備註： 1、擔服週間巡邏勤務，請著整齊服裝(勤務帽、制服、勤務鞋)，提前5-10分鐘至總隊值星隊簽到，並領取無線電、巡邏表及相關配件。 2、請同學互相提醒值勤時間，切勿脫勤。 3、如有疑問(如衝堂、因故無法值班等)，請向勤務排表員921127江睿承(B218)、921165謝頡譯(B218)反應。 4、本表公布後，請同學於自己名字下方簽名(押時間)確認，如需更改，請報由區隊長核章修正，若收假前未簽名確認者，將依規定記點處分。

Sheet 114-2_W1寢巡
A1: 中央警察大學 92期1隊 114學年度第2學期 寢巡勤務表 (第1週)
A2: 日期 | B2: 3月6日
A3: 星期 | B3: 五
A4: 10：00- 12：00 | B4: 79 | C4: 劉丞量
B6: 141 | C6: 陳冠璋
B8: 233 | C8: 趙承泰
A10: 備註： 1、輪值勤務，請同學務必提早5-10分鐘到勤。 2、請同學互相提醒值勤時間，特別是夜間值班同學。 3、如有疑問(如衝堂、因故無法值班等)，請向勤務排表員921127江睿承(B218)、921165謝頡譯(B218)反應。 4、本表公布後，請同學於自己名字下方簽名(押時間)確認，如需更改，請報由區隊長核章修正，收假前未簽名確認者，將依規定記點處分。

Sheet 空堂表
A1: 星期 | B1: 節次 / 值班時段 | C1: 空堂系數 | D1: 空堂系別
A2: 週一 | B2: 第1–2節 → 0800-1000 | C2: 10/17 | D2: 犯預、犯矯、交通（交交）、交通（交電）、國境管理、國境移民、行管、安全情報、法律、行政系
A3: 週一 | B3: 第3–4節 → 1000-1200 | C3: 4/17 | D3: 犯預、外事、安全安全、消防
A4: 週一 | B4: 第5節 → 1200-1350 | C4: 15/17 | D4: 犯矯、資管、鑑識、交通（交電）、外事、安全安全、水上、國境管理、國境移民、刑事、行管、安全情報、消防、法律、行政系
A5: 週一 | B5: 第6–7節 → 1350-1600 | C5: 2/17 | D5: 水上、安全情報
A6: 週一 | B6: 第8–9節 → 1600-1800 | C6: 0/17 | D6: 無
A8: 週二 | B8: 第1–2節 → 0800-1000 | C8: 5/17 | D8: 犯預、犯矯、外事、刑事、消防
A9: 週二 | B9: 第3–4節 → 1000-1200 | C9: 5/17 | D9: 犯預、犯矯、鑑識、交通（交電）、法律
A10: 週二 | B10: 第5節 → 1200-1350 | C10: 14/17 | D10: 資管、鑑識、交通（交電）、外事、安全安全、水上、國境管理、國境移民、刑事、行管、安全情報、消防、法律、行政系
A11: 週二 | B11: 第6–7節 → 1350-1600 | C11: 3/17 | D11: 交通（交電）、刑事、消防
A12: 週二 | B12: 第8節 → 1600-1800 | C12: 4/17 | D12: 安全安全、行管、安全情報、行政系
A13: 週二 | B13: 第9節 → 1600-1800 | C13: 6/17 | D13: 鑑識、安全安全、行管、安全情報、法律、行政系
... A33: 週五 | B33: 第9節 → 1600-1800 | C33: 15/17 | D33: 犯預、犯矯、資管、鑑識、交通（交交）、交通（交電）、外事、安全安全、水上、國境管理、國境移民、行管、安全情報、消防、行政系

Sheet 114-2_W1_夜巡
A1: 中央警察大學 92期1隊 114學年度第2學期友誼、警英夜巡勤務表 (第1週)
A2: 日期 | B2: 3月1日 | D2: 3月2日 | F2: 3月3日 | H2: 3月4日 | J2: 3月5日 | L2: 3月6日
A3: 星期 | B3: 日 | D3: 一 | F3: 二 | H3: 三 | J3: 四 | L3: 五
A4: 01：00- 03：00 | B4: 放假 | D4: 1 | E4: 胡迎翔 | F4: 209 | G4: 何宇評 | H4: 92 | I4: 劉晉瑋 | J4: 67 | K4: 瑪婻．澫口口 | L4: 9 | M4: 簡宏吉
D6: 239 | E6: 梁庭瀚 | F6: 272 | G6: 洪睿辰 | H6: 273 | I6: 江翊嘉 | J6: 191 | K6: 林士玄 | L6: 213 | M6: 沈宸右
A8: 03：00- 05：00 | D8: 30 | E8: 陳子衡 | F8: 103 | G8: 梁嘉程 | H8: 73 | I8: 王捷 | J8: 5 | K8: 詹祥佑 | L8: 39 | M8: 林智心
D10: 34 | E10: 黃仲君 | F10: 243 | G10: 簡揆峰 | H10: 218 | I10: 林弘諺 | J10: 276 | K10: 蘇靖翔 | L10: 86 | M10: 王御丞
A12: 23：00- 01：00 | B12: 153 | C12: 吳宥陞 | D12: 107 | E12: 高振碩 | F12: 35 | G12: 陳彥詔 | H12: 126 | I12: 劉承均 | J12: 177 | K12: 林恩祈 | L12: 放假
B14: 162 | C14: 林上文 | D14: 125 | E14: 韋榮業 | F14: 111 | G14: 王俊凱 | H14: 168 | I14: 丁友竣 | J14: 257 | K14: 林文斌
A16: 備註： 1、擔服週間巡邏勤務，請著整齊服裝(勤務帽、制服、勤務鞋)，提前5-10分鐘至總隊值星隊簽到，並領取無線電、巡邏表及相關配件。 2、請同學互相提醒值勤時間，切勿脫勤。 3、如有疑問(如衝堂、因故無法值班等)，請向勤務排表員921127江睿承(B218)、921165謝頡譯(B218)反應。 4、本表公布後，請同學於自己名字下方簽名(押時間)確認，如需更改，請報由區隊長核章修正，若收假前未簽名確認者，將依規定記點處分。

Sheet 勤務時數總表
A1: 學號 | B1: 姓名 | C1: 性別 | D1: 系別 | E1: 隊部值班 | F1: 警英、友誼夜巡時數 | G1: 假日校巡時數 | H1: 警技館值班時數 | I1: 週間校巡時數 | J1: 寢巡 | K1: 監廚 | L1: 實習幹部 | M1: 勤務總時數 | N1: 寢巡次數 | O1: 監廚次數 | P1: 備註
A2: 1 | B2: 胡迎翔 | C2: 男 | D2: 行政系 | M2: =E2+H2+G2+I2+F2+J2+K2+L2 -> 0 | N2: =J2 -> 0 | O2: =K2 -> 0 | Q2: 19周值班
A3: 2 | B3: 方聖文 | C3: 男 | D3: 行政系 | M3: =E3+H3+G3+I3+F3+J3+K3+L3 -> 0 | N3: =J3 -> 0 | O3: =K3 -> 0
A4: 3 | B4: 廖子宏 | C4: 男 | D4: 行政系 | M4: =E4+H4+G4+I4+F4+J4+K4+L4 -> 0 | N4: =J4 -> 0 | O4: =K4 -> 0 | Q4: 15周監廚
A5: 4 | B5: 王湘霖 | C5: 男 | D5: 行政系 | M5: =E5+H5+G5+I5+F5+J5+K5+L5 -> 0 | N5: =J5 -> 0 | O5: =K5 -> 0 | Q5: 15周值班
A6: 5 | B6: 詹祥佑 | C6: 男 | D6: 行政系 | M6: =E6+H6+G6+I6+F6+J6+K6+L6 -> 0 | N6: =J6 -> 0 | O6: =K6 -> 0
A7: 6 | B7: 陳彥安 | C7: 男 | D7: 行政系 | M7: =E7+H7+G7+I7+F7+J7+K7+L7 -> 0 | N7: =J7 -> 0 | O7: =K7 -> 0
A8: 7 | B8: 沈佳成 | C8: 男 | D8: 行政系 | M8: =E8+H8+G8+I8+F8+J8+K8+L8 -> 0 | N8: =J8 -> 0 | O8: =K8 -> 0
A9: 8 | B9: 林冠言 | C9: 男 | D9: 行政系 | M9: =E9+H9+G9+I9+F9+J9+K9+L9 -> 0 | N9: =J9 -> 0 | O9: =K9 -> 0
A10: 9 | B10: 簡宏吉 | C10: 男 | D10: 行政系 | M10: =E10+H10+G10+I10+F10+J10+K10+L10 -> 0 | N10: =J10 -> 0 | O10: =K10 -> 0
A11: 10 | B11: 林心鈺 | C11: 男 | D11: 行政系 | M11: =E11+H11+G11+I11+F11+J11+K11+L11 -> 0 | N11: =J11 -> 0 | O11: =K11 -> 0
A12: 11 | B12: 吳兆陽 | C12: 男 | D12: 行政系 | M12: =E12+H12+G12+I12+F12+J12+K12+L12 -> 0 | N12: =J12 -> 0 | O12: =K12 -> 0
A13: 12 | B13: 林軒宇 | C13: 男 | D13: 犯防系預防組 | M13: =E13+H13+G13+I13+F13+J13+K13+L13 -> 0 | N13: =J13 -> 0 | O13: =K13 -> 0
A14: 13 | B14: 吳柏緯 | C14: 男 | D14: 行政系 | M14: =E14+H14+G14+I14+F14+J14+K14+L14 -> 0 | N14: =J14 -> 0 | O14: =K14 -> 0
A15: 14 | B15: 陳泊諺 | C15: 男 | D15: 行政系 | M15: =E15+H15+G15+I15+F15+J15+K15+L15 -> 0 | N15: =J15 -> 0 | O15: =K15 -> 0
A16: 15 | B16: 鄭弘侖 | C16: 男 | D16: 行政系 | M16: =E16+H16+G16+I16+F16+J16+K16+L16 -> 0 | N16: =J16 -> 0 | O16: =K16 -> 0
A17: 16 | B17: 張宜凱 | C17: 男 | D17: 行政系 | M17: =E17+H17+G17+I17+F17+J17+K17+L17 -> 0 | N17: =J17 -> 0 | O17: =K17 -> 0
... A103: 104 | B103: 何旻祐 | C103: 男 | D103: 消防系災防組 | M103: =E103+H103+G103+I103+F103+J103+K103+L103 -> 0 | N103: =J103 -> 0 | O103: =K103 -> 0
A104: 105 | B104: 退學 | M104: =E104+H104+G104+I104+F104+J104+K104+L104 -> 0 | N104: =J104 -> 0 | O104: =K104 -> 0
A105: 106 | B105: 張勝皓 | C105: 男 | D105: 消防系災防組 | M105: =E105+H105+G105+I105+F105+J105+K105+L105 -> 0 | N105: =J105 -> 0 | O105: =K105 -> 0
A106: 107 | B106: 高振碩 | C106: 男 | D106: 消防系災防組 | M106: =E106+H106+G106+I106+F106+J106+K106+L106 -> 0 | N106: =J106 -> 0 | O106: =K106 -> 0
A107: 108 | B107: 楊安琪 | C107: 女 | D107: 消防系災防組 | M107: =E107+H107+G107+I107+F107+J107+K107+L107 -> 0 | N107: =J107 -> 0 | O107: =K107 -> 0
A108: 109 | B108: 𡍼又諠 | C108: 女 | D108: 消防系災防組 | M108: =E108+H108+G108+I108+F108+J108+K108+L108 -> 0 | N108: =J108 -> 0 | O108: =K108 -> 0
A109: 110 | B109: 李柏琳 | C109: 男 | D109: 消防系消防組 | M109: =E109+H109+G109+I109+F109+J109+K109+L109 -> 0 | N109: =J109 -> 0 | O109: =K109 -> 0
A110: 111 | B110: 王俊凱 | C110: 男 | D110: 消防系消防組 | M110: =E110+H110+G110+I110+F110+J110+K110+L110 -> 0 | N110: =J110 -> 0 | O110: =K110 -> 0
A111: 112 | B111: 何柏廷 | C111: 男 | D111: 消防系消防組 | M111: =E111+H111+G111+I111+F111+J111+K111+L111 -> 0 | N111: =J111 -> 0 | O111: =K111 -> 0
A112: 113 | B112: 馬家騏 | C112: 男 | D112: 消防系消防組 | M112: =E112+H112+G112+I112+F112+J112+K112+L112 -> 0 | N112: =J112 -> 0 | O112: =K112 -> 0
A113: 114 | B113: 彭楷峰 | C113: 男 | D113: 消防系消防組 | M113: =E113+H113+G113+I113+F113+J113+K113+L113 -> 0 | N113: =J113 -> 0 | O113: =K113 -> 0
A114: 115 | B114: 陳竑旭 | C114: 男 | D114: 消防系消防組 | M114: =E114+H114+G114+I114+F114+J114+K114+L114 -> 0 | N114: =J114 -> 0 | O114: =K114 -> 0
A115: 116 | B115: 李建陞 | C115: 男 | D115: 消防系消防組 | M115: =E115+H115+G115+I115+F115+J115+K115+L115 -> 0 | N115: =J115 -> 0 | O115: =K115 -> 0
A116: 117 | B116: 林佳澤 | C116: 男 | D116: 消防系消防組 | M116: =E116+H116+G116+I116+F116+J116+K116+L116 -> 0 | N116: =J116 -> 0 | O116: =K116 -> 0
... A118: 119 | B118: 劉彩玉 | C118: 女 | D118: 消防系消防組 | M118: =E118+H118+G118+I118+F118+J118+K118+L118 -> 0 | N118: =J118 -> 0 | O118: =K118 -> 0
A119: 120 | B119: 胡耕綸 | C119: 男 | D119: 交通系交通組 | M119: =E119+H119+G119+I119+F119+J119+K119+L119 -> 0 | N119: =J119 -> 0 | O119: =K119 -> 0 | S119: 監廚11周
A120: 121 | B120: 劉鎧霆 | C120: 男 | D120: 交通系交通組 | M120: =E120+H120+G120+I120+F120+J120+K120+L120 -> 0 | N120: =J120 -> 0 | O120: =K120 -> 0
A121: 122 | B121: 黃翊愷 | C121: 男 | D121: 交通系交通組 | M121: =E121+H121+G121+I121+F121+J121+K121+L121 -> 0 | N121: =J121 -> 0 | O121: =K121 -> 0
A122: 123 | B122: 施瑀修 | C122: 男 | D122: 交通系交通組 | M122: =E122+H122+G122+I122+F122+J122+K122+L122 -> 0 | N122: =J122 -> 0 | O122: =K122 -> 0
A123: 124 | B123: 許燿安 | C123: 男 | D123: 交通系交通組 | M123: =E123+H123+G123+I123+F123+J123+K123+L123 -> 0 | N123: =J123 -> 0 | O123: =K123 -> 0
A124: 125 | B124: 韋榮業 | C124: 男 | D124: 交通系交通組 | M124: =E124+H124+G124+I124+F124+J124+K124+L124 -> 0 | N124: =J124 -> 0 | O124: =K124 -> 0
A125: 126 | B125: 劉承均 | C125: 男 | D125: 交通系交通組 | M125: =E125+H125+G125+I125+F125+J125+K125+L125 -> 0 | N125: =J125 -> 0 | O125: =K125 -> 0
A126: 127 | B126: 江睿承 | C126: 男 | D126: 交通系交通組 | M126: =E126+H126+G126+I126+F126+J126+K126+L126 -> 0 | N126: =J126 -> 0 | O126: =K126 -> 0
...
